<?xml version="1.0" ?>
<!-- =================================================================================== -->
<!-- |    This document was autogenerated by xacro from robot.urdf.xacro               | -->
<!-- |    EDITING THIS FILE BY HAND IS NOT RECOMMENDED                                 | -->
<!-- =================================================================================== -->
<robot name="robot">
  <!-- <xacro:include filename="$(find robot_description)/urdf/gazebo.urdf.xacro" /> -->
  <material name="white">
    <color rgba="1 1 1 1"/>
  </material>
  <material name="orange">
    <color rgba="1 0.3 0.1 1"/>
  </material>
  <material name="blue">
    <color rgba="0.2 0.2 1 1"/>
  </material>
  <material name="black">
    <color rgba="0 0 0 1"/>
  </material>
  <material name="red">
    <color rgba="1 0 0 1"/>
  </material>
  <material name="pink">
    <color rgba="0.8 0 0.8 1"/>
  </material>
  <link name="base_link">
    </link>
  <link name="base_footprint">
    </link>
  <joint name="base_footprint_joint" type="fixed">
    <parent link="base_link"/>
    <child link="base_footprint"/>
    <origin rpy="0 0 0" xyz="0 0 -0.138"/>
  </joint>
  <joint name="chassis_joint" type="fixed">
    <parent link="base_link"/>
    <child link="chassis"/>
    <origin xyz="-0.226 0 -0.01"/>
  </joint>
  <link name="chassis">
    <inertial>
      <origin rpy="0 0 0" xyz="0.1675 0 0.025"/>
      <mass value="1.0"/>
      <inertia ixx="0.006060416666666667" ixy="0.0" ixz="0.0" iyy="0.009560416666666668" iyz="0.0" izz="0.015204166666666668"/>
    </inertial>
    <visual>
      <origin xyz="0.1675 0 0.025"/>
      <geometry>
        <box size="0.335 0.265 0.05"/>
      </geometry>
      <material name="orange"/>
    </visual>
    <collision>
      <origin xyz="0.1675 0 0.025"/>
      <geometry>
        <box size="0.335 0.265 0.05"/>
      </geometry>
    </collision>
  </link>
  <link name="body">
    <visual>
      <geometry>
        <cylinder length="0.35" radius="0.13"/>
      </geometry>
      <material name="pink"/>
    </visual>
    <collision>
      <geometry>
        <cylinder length="0.35" radius="0.13"/>
      </geometry>
    </collision>
    <inertial>
      <mass value="0.1"/>
      <inertia ixx="0.0014433333333333334" ixy="0.0" ixz="0.0" iyy="0.0014433333333333334" iyz="0.0" izz="0.002275"/>
    </inertial>
  </link>
  <joint name="body_joint" type="fixed">
    <parent link="chassis"/>
    <child link="body"/>
    <origin rpy="0 0 0" xyz="0.16 0 0.225"/>
  </joint>
  <link name="head">
    <visual>
      <geometry>
        <box size="0.16 0.16 0.16"/>
      </geometry>
      <material name="white"/>
    </visual>
    <collision>
      <geometry>
        <box size="0.16 0.16 0.16"/>
      </geometry>
    </collision>
    <inertial>
      <mass value="0.1"/>
      <inertia ixx="0.00042666666666666667" ixy="0.0" ixz="0.0" iyy="0.00042666666666666667" iyz="0.0" izz="0.00042666666666666667"/>
    </inertial>
  </link>
  <joint name="head_joint" type="fixed">
    <parent link="body"/>
    <child link="head"/>
    <origin rpy="0 0 0" xyz="0 0 0.25"/>
  </joint>
  <link name="right_antenna">
    <visual>
      <geometry>
        <box size="0.02 0.02 0.05"/>
      </geometry>
      <material name="black"/>
    </visual>
    <collision>
      <geometry>
        <box size="0.02 0.02 0.05"/>
      </geometry>
      <origin rpy="0 1.57075 0" xyz="0 0 0"/>
    </collision>
    <inertial>
      <mass value="0.2"/>
      <inertia ixx="4.833333333333335e-05" ixy="0.0" ixz="0.0" iyy="4.833333333333335e-05" iyz="0.0" izz="1.3333333333333333e-05"/>
    </inertial>
  </link>
  <joint name="right_antenna_joint" type="fixed">
    <parent link="head"/>
    <child link="right_antenna"/>
    <origin rpy="0 0 0" xyz="0 0.045 0.11"/>
  </joint>
  <link name="left_antenna">
    <visual>
      <geometry>
        <box size="0.02 0.02 0.05"/>
      </geometry>
      <material name="black"/>
    </visual>
    <collision>
      <geometry>
        <box size="0.02 0.02 0.05"/>
      </geometry>
      <origin rpy="0 1.57075 0" xyz="0 0 0"/>
    </collision>
    <inertial>
      <mass value="0.2"/>
      <inertia ixx="4.833333333333335e-05" ixy="0.0" ixz="0.0" iyy="4.833333333333335e-05" iyz="0.0" izz="1.3333333333333333e-05"/>
    </inertial>
  </link>
  <joint name="left_antenna_joint" type="fixed">
    <parent link="head"/>
    <child link="left_antenna"/>
    <origin rpy="0 0 0" xyz="0 -0.045 0.11"/>
  </joint>
  <link name="right_eye">
    <visual>
      <geometry>
        <box size="0.025 0.025 0.025"/>
      </geometry>
      <material name="black"/>
    </visual>
    <collision>
      <geometry>
        <box size="0.025 0.025 0.025"/>
      </geometry>
      <origin rpy="0 1.57075 0" xyz="0 0 0"/>
    </collision>
    <inertial>
      <mass value="0.05"/>
      <inertia ixx="5.208333333333334e-06" ixy="0.0" ixz="0.0" iyy="5.208333333333334e-06" iyz="0.0" izz="5.208333333333334e-06"/>
    </inertial>
  </link>
  <joint name="right_eye_joint" type="fixed">
    <parent link="head"/>
    <child link="right_eye"/>
    <origin rpy="0 0 0" xyz="0.085 0.045 0.015"/>
  </joint>
  <link name="left_eye">
    <visual>
      <geometry>
        <box size="0.025 0.025 0.025"/>
      </geometry>
      <material name="black"/>
    </visual>
    <collision>
      <geometry>
        <box size="0.025 0.025 0.025"/>
      </geometry>
      <origin rpy="0 1.57075 0" xyz="0 0 0"/>
    </collision>
    <inertial>
      <mass value="0.05"/>
      <inertia ixx="5.208333333333334e-06" ixy="0.0" ixz="0.0" iyy="5.208333333333334e-06" iyz="0.0" izz="5.208333333333334e-06"/>
    </inertial>
  </link>
  <joint name="left_eye_joint" type="fixed">
    <parent link="head"/>
    <child link="left_eye"/>
    <origin rpy="0 0 0" xyz="0.085 -0.045 0.015"/>
  </joint>
  <link name="mouth">
    <visual>
      <geometry>
        <box size="0.02 0.08 0.02"/>
      </geometry>
      <material name="red"/>
    </visual>
    <collision>
      <geometry>
        <box size="0.02 0.08 0.02"/>
      </geometry>
      <origin rpy="0 1.57075 0" xyz="0 0 0"/>
    </collision>
    <inertial>
      <mass value="0.15"/>
      <inertia ixx="8.499999999999999e-05" ixy="0.0" ixz="0.0" iyy="9.999999999999999e-06" iyz="0.0" izz="8.499999999999999e-05"/>
    </inertial>
  </link>
  <joint name="mouth_joint" type="fixed">
    <parent link="head"/>
    <child link="mouth"/>
    <origin rpy="0 0 0" xyz="0.085 0 -0.04"/>
  </joint>
  <gazebo reference="chassis">
    <material>Gazebo/Orange</material>
  </gazebo>
  <joint name="left_wheel_joint" type="continuous">
    <parent link="base_link"/>
    <child link="left_wheel"/>
    <origin rpy="-1.5707963267948966 0 0" xyz="0 0.1485 0"/>
    <axis xyz="0 0 1"/>
  </joint>
  <link name="left_wheel">
    <visual>
      <geometry>
        <cylinder length="0.026" radius="0.033"/>
      </geometry>
      <material name="blue"/>
    </visual>
    <collision>
      <geometry>
        <sphere radius="0.033"/>
      </geometry>
    </collision>
    <inertial>
      <origin rpy="0 0 0" xyz="0 0 0"/>
      <mass value="0.05"/>
      <inertia ixx="1.642916666666667e-05" ixy="0.0" ixz="0.0" iyy="1.642916666666667e-05" iyz="0.0" izz="2.7225000000000004e-05"/>
    </inertial>
  </link>
  <gazebo reference="left_wheel">
    <material>Gazebo/Blue</material>
  </gazebo>
  <joint name="right_wheel_joint" type="continuous">
    <parent link="base_link"/>
    <child link="right_wheel"/>
    <origin rpy="1.5707963267948966 0 0" xyz="0 -0.1485 0"/>
    <axis xyz="0 0 -1"/>
  </joint>
  <link name="right_wheel">
    <visual>
      <geometry>
        <cylinder length="0.026" radius="0.033"/>
      </geometry>
      <material name="blue"/>
    </visual>
    <collision>
      <geometry>
        <sphere radius="0.033"/>
      </geometry>
    </collision>
    <inertial>
      <origin rpy="0 0 0" xyz="0 0 0"/>
      <mass value="0.05"/>
      <inertia ixx="1.642916666666667e-05" ixy="0.0" ixz="0.0" iyy="1.642916666666667e-05" iyz="0.0" izz="2.7225000000000004e-05"/>
    </inertial>
  </link>
  <gazebo reference="right_wheel">
    <material>Gazebo/Blue</material>
  </gazebo>
  <joint name="caster_wheel_joint" type="fixed">
    <parent link="chassis"/>
    <child link="caster_wheel"/>
    <origin xyz="0.075 0 -0.013"/>
  </joint>
  <link name="caster_wheel">
    <visual>
      <geometry>
        <sphere radius="0.01"/>
      </geometry>
      <material name="white"/>
    </visual>
    <collision>
      <geometry>
        <sphere radius="0.01"/>
      </geometry>
    </collision>
    <inertial>
      <origin rpy="0 0 0" xyz="0 0 0"/>
      <mass value="0.01"/>
      <inertia ixx="4.0000000000000003e-07" ixy="0.0" ixz="0.0" iyy="4.0000000000000003e-07" iyz="0.0" izz="4.0000000000000003e-07"/>
    </inertial>
  </link>
  <gazebo reference="caster_wheel">
    <material>Gazebo/White</material>
    <mu1 value="0.001"/>
    <mu2 value="0.001"/>
  </gazebo>
</robot>
